2021-03-28 16:56:36,636 INFO: GLauth Management UI [in /home/nils/python/ldap/app/__init__.py:48]
2021-03-28 16:56:55,912 INFO: GLauth Management UI [in /home/nils/python/ldap/app/__init__.py:48]
2021-03-28 16:58:29,351 INFO: GLauth Management UI [in /home/nils/python/ldap/app/__init__.py:48]
2021-03-28 16:58:51,603 INFO: GLauth Management UI [in /home/nils/python/ldap/app/__init__.py:48]
2021-03-28 17:01:26,437 INFO: GLauth Management UI [in /home/nils/python/ldap/app/__init__.py:48]
2021-03-28 21:10:06,614 INFO: GLauth Management UI [in /home/nils/python/ldap/app/__init__.py:48]
2021-03-29 16:36:09,020 INFO: GLauth Management UI [in /home/nils/python/ldap/app/__init__.py:48]
2021-03-30 14:30:56,653 INFO: GLauth Management UI [in /home/nils/python/ldap/app/__init__.py:50]
2021-03-30 14:32:34,989 INFO: GLauth Management UI [in /home/nils/python/ldap/app/__init__.py:50]
2021-03-30 14:54:05,776 INFO: GLauth Management UI [in /home/nils/python/ldap/app/__init__.py:51]
2021-03-30 15:05:19,304 INFO: GLauth Management UI [in /home/nils/python/ldap/app/__init__.py:51]
2021-03-30 15:05:42,967 INFO: GLauth Management UI [in /home/nils/python/ldap/app/__init__.py:51]
2021-03-30 15:05:59,025 ERROR: Exception on /testmail [POST] [in /home/nils/python/ldap/venv/lib/python3.8/site-packages/flask/app.py:1891]
Traceback (most recent call last):
  File "/home/nils/python/ldap/venv/lib/python3.8/site-packages/flask/app.py", line 2447, in wsgi_app
    response = self.full_dispatch_request()
  File "/home/nils/python/ldap/venv/lib/python3.8/site-packages/flask/app.py", line 1952, in full_dispatch_request
    rv = self.handle_user_exception(e)
  File "/home/nils/python/ldap/venv/lib/python3.8/site-packages/flask/app.py", line 1821, in handle_user_exception
    reraise(exc_type, exc_value, tb)
  File "/home/nils/python/ldap/venv/lib/python3.8/site-packages/flask/_compat.py", line 39, in reraise
    raise value
  File "/home/nils/python/ldap/venv/lib/python3.8/site-packages/flask/app.py", line 1950, in full_dispatch_request
    rv = self.dispatch_request()
  File "/home/nils/python/ldap/venv/lib/python3.8/site-packages/flask/app.py", line 1936, in dispatch_request
    return self.view_functions[rule.endpoint](**req.view_args)
  File "/home/nils/python/ldap/venv/lib/python3.8/site-packages/flask_login/utils.py", line 272, in decorated_view
    return func(*args, **kwargs)
  File "/home/nils/python/ldap/app/routes.py", line 28, in testmail
    send_test_mail_email(form.mail.data)
NameError: name 'send_test_mail_email' is not defined
2021-03-30 15:17:57,867 INFO: GLauth Management UI [in /home/nils/python/ldap/app/__init__.py:51]
2021-03-30 15:18:08,977 ERROR: Exception on /testmail [POST] [in /home/nils/python/ldap/venv/lib/python3.8/site-packages/flask/app.py:1891]
Traceback (most recent call last):
  File "/home/nils/python/ldap/venv/lib/python3.8/site-packages/flask/app.py", line 2447, in wsgi_app
    response = self.full_dispatch_request()
  File "/home/nils/python/ldap/venv/lib/python3.8/site-packages/flask/app.py", line 1952, in full_dispatch_request
    rv = self.handle_user_exception(e)
  File "/home/nils/python/ldap/venv/lib/python3.8/site-packages/flask/app.py", line 1821, in handle_user_exception
    reraise(exc_type, exc_value, tb)
  File "/home/nils/python/ldap/venv/lib/python3.8/site-packages/flask/_compat.py", line 39, in reraise
    raise value
  File "/home/nils/python/ldap/venv/lib/python3.8/site-packages/flask/app.py", line 1950, in full_dispatch_request
    rv = self.dispatch_request()
  File "/home/nils/python/ldap/venv/lib/python3.8/site-packages/flask/app.py", line 1936, in dispatch_request
    return self.view_functions[rule.endpoint](**req.view_args)
  File "/home/nils/python/ldap/venv/lib/python3.8/site-packages/flask_login/utils.py", line 272, in decorated_view
    return func(*args, **kwargs)
  File "/home/nils/python/ldap/app/routes.py", line 28, in testmail
    send_test_mail_email(form.mail.data)
NameError: name 'send_test_mail_email' is not defined
2021-03-30 15:19:50,254 INFO: GLauth Management UI [in /home/nils/python/ldap/app/__init__.py:51]
2021-03-30 15:20:03,999 ERROR: Exception on /testmail [POST] [in /home/nils/python/ldap/venv/lib/python3.8/site-packages/flask/app.py:1891]
Traceback (most recent call last):
  File "/home/nils/python/ldap/venv/lib/python3.8/site-packages/flask/app.py", line 2447, in wsgi_app
    response = self.full_dispatch_request()
  File "/home/nils/python/ldap/venv/lib/python3.8/site-packages/flask/app.py", line 1952, in full_dispatch_request
    rv = self.handle_user_exception(e)
  File "/home/nils/python/ldap/venv/lib/python3.8/site-packages/flask/app.py", line 1821, in handle_user_exception
    reraise(exc_type, exc_value, tb)
  File "/home/nils/python/ldap/venv/lib/python3.8/site-packages/flask/_compat.py", line 39, in reraise
    raise value
  File "/home/nils/python/ldap/venv/lib/python3.8/site-packages/flask/app.py", line 1950, in full_dispatch_request
    rv = self.dispatch_request()
  File "/home/nils/python/ldap/venv/lib/python3.8/site-packages/flask/app.py", line 1936, in dispatch_request
    return self.view_functions[rule.endpoint](**req.view_args)
  File "/home/nils/python/ldap/venv/lib/python3.8/site-packages/flask_login/utils.py", line 272, in decorated_view
    return func(*args, **kwargs)
  File "/home/nils/python/ldap/app/routes.py", line 28, in testmail
    send_test_mail(form.mail.data)
NameError: name 'send_test_mail' is not defined
2021-03-30 15:20:50,897 INFO: GLauth Management UI [in /home/nils/python/ldap/app/__init__.py:51]
2021-03-30 15:21:02,105 ERROR: Exception on /testmail [POST] [in /home/nils/python/ldap/venv/lib/python3.8/site-packages/flask/app.py:1891]
Traceback (most recent call last):
  File "/home/nils/python/ldap/venv/lib/python3.8/site-packages/flask/app.py", line 2447, in wsgi_app
    response = self.full_dispatch_request()
  File "/home/nils/python/ldap/venv/lib/python3.8/site-packages/flask/app.py", line 1952, in full_dispatch_request
    rv = self.handle_user_exception(e)
  File "/home/nils/python/ldap/venv/lib/python3.8/site-packages/flask/app.py", line 1821, in handle_user_exception
    reraise(exc_type, exc_value, tb)
  File "/home/nils/python/ldap/venv/lib/python3.8/site-packages/flask/_compat.py", line 39, in reraise
    raise value
  File "/home/nils/python/ldap/venv/lib/python3.8/site-packages/flask/app.py", line 1950, in full_dispatch_request
    rv = self.dispatch_request()
  File "/home/nils/python/ldap/venv/lib/python3.8/site-packages/flask/app.py", line 1936, in dispatch_request
    return self.view_functions[rule.endpoint](**req.view_args)
  File "/home/nils/python/ldap/venv/lib/python3.8/site-packages/flask_login/utils.py", line 272, in decorated_view
    return func(*args, **kwargs)
  File "/home/nils/python/ldap/app/routes.py", line 28, in testmail
    send_test_mail(form.mail.data)
  File "/home/nils/python/ldap/app/email.py", line 19, in send_test_mail
    send_email('[{}] TEST MAIL'.format(app.config['APPNAME']),
TypeError: send_email() missing 1 required positional argument: 'html_body'
2021-03-30 15:22:47,967 INFO: GLauth Management UI [in /home/nils/python/ldap/app/__init__.py:51]
2021-03-30 15:57:04,475 INFO: GLauth Management UI [in /home/nils/python/ldap/app/__init__.py:51]
2021-03-30 16:05:30,727 INFO: GLauth Management UI [in /home/nils/python/ldap/app/__init__.py:51]
