2021-03-27 12:51:32,239 INFO: GLauth Management UI [in /home/nils/python/ldap/app/__init__.py:48]
2021-03-27 12:54:57,333 INFO: GLauth Management UI [in /home/nils/python/ldap/app/__init__.py:48]
2021-03-27 12:55:00,917 ERROR: Exception on /admin/user/edit/ [GET] [in /home/nils/python/ldap/venv/lib/python3.8/site-packages/flask/app.py:1891]
Traceback (most recent call last):
  File "/home/nils/python/ldap/venv/lib/python3.8/site-packages/flask/app.py", line 2447, in wsgi_app
    response = self.full_dispatch_request()
  File "/home/nils/python/ldap/venv/lib/python3.8/site-packages/flask/app.py", line 1952, in full_dispatch_request
    rv = self.handle_user_exception(e)
  File "/home/nils/python/ldap/venv/lib/python3.8/site-packages/flask/app.py", line 1821, in handle_user_exception
    reraise(exc_type, exc_value, tb)
  File "/home/nils/python/ldap/venv/lib/python3.8/site-packages/flask/_compat.py", line 39, in reraise
    raise value
  File "/home/nils/python/ldap/venv/lib/python3.8/site-packages/flask/app.py", line 1950, in full_dispatch_request
    rv = self.dispatch_request()
  File "/home/nils/python/ldap/venv/lib/python3.8/site-packages/flask/app.py", line 1936, in dispatch_request
    return self.view_functions[rule.endpoint](**req.view_args)
  File "/home/nils/python/ldap/venv/lib/python3.8/site-packages/flask_admin/base.py", line 69, in inner
    return self._run_view(f, *args, **kwargs)
  File "/home/nils/python/ldap/venv/lib/python3.8/site-packages/flask_admin/base.py", line 368, in _run_view
    return fn(self, *args, **kwargs)
  File "/home/nils/python/ldap/venv/lib/python3.8/site-packages/flask_admin/model/base.py", line 2138, in edit_view
    form = self.edit_form(obj=model)
  File "/home/nils/python/ldap/app/adminview.py", line 114, in edit_form
    form.send_password_reset_email.label = "Send Password Reset Link"
AttributeError: 'UserForm' object has no attribute 'send_password_reset_email'
2021-03-27 12:55:43,490 INFO: GLauth Management UI [in /home/nils/python/ldap/app/__init__.py:48]
2021-03-27 12:55:51,488 ERROR: Exception on /admin/user/edit/ [GET] [in /home/nils/python/ldap/venv/lib/python3.8/site-packages/flask/app.py:1891]
Traceback (most recent call last):
  File "/home/nils/python/ldap/venv/lib/python3.8/site-packages/flask/app.py", line 2447, in wsgi_app
    response = self.full_dispatch_request()
  File "/home/nils/python/ldap/venv/lib/python3.8/site-packages/flask/app.py", line 1952, in full_dispatch_request
    rv = self.handle_user_exception(e)
  File "/home/nils/python/ldap/venv/lib/python3.8/site-packages/flask/app.py", line 1821, in handle_user_exception
    reraise(exc_type, exc_value, tb)
  File "/home/nils/python/ldap/venv/lib/python3.8/site-packages/flask/_compat.py", line 39, in reraise
    raise value
  File "/home/nils/python/ldap/venv/lib/python3.8/site-packages/flask/app.py", line 1950, in full_dispatch_request
    rv = self.dispatch_request()
  File "/home/nils/python/ldap/venv/lib/python3.8/site-packages/flask/app.py", line 1936, in dispatch_request
    return self.view_functions[rule.endpoint](**req.view_args)
  File "/home/nils/python/ldap/venv/lib/python3.8/site-packages/flask_admin/base.py", line 69, in inner
    return self._run_view(f, *args, **kwargs)
  File "/home/nils/python/ldap/venv/lib/python3.8/site-packages/flask_admin/base.py", line 368, in _run_view
    return fn(self, *args, **kwargs)
  File "/home/nils/python/ldap/venv/lib/python3.8/site-packages/flask_admin/model/base.py", line 2138, in edit_view
    form = self.edit_form(obj=model)
  File "/home/nils/python/ldap/app/adminview.py", line 114, in edit_form
    form.send_pw_reset_email.label = "Send Password Reset Link"
AttributeError: 'UserForm' object has no attribute 'send_pw_reset_email'
2021-03-27 12:56:11,276 INFO: GLauth Management UI [in /home/nils/python/ldap/app/__init__.py:48]
2021-03-27 12:59:18,667 INFO: GLauth Management UI [in /home/nils/python/ldap/app/__init__.py:48]
2021-03-27 13:01:39,595 INFO: GLauth Management UI [in /home/nils/python/ldap/app/__init__.py:48]
2021-03-27 13:05:25,755 INFO: GLauth Management UI [in /home/nils/python/ldap/app/__init__.py:48]
2021-03-27 13:10:44,293 INFO: GLauth Management UI [in /home/nils/python/ldap/app/__init__.py:48]
2021-03-27 13:13:03,573 INFO: GLauth Management UI [in /home/nils/python/ldap/app/__init__.py:48]
2021-03-27 13:14:12,907 INFO: GLauth Management UI [in /home/nils/python/ldap/app/__init__.py:48]
2021-03-27 13:19:25,056 INFO: GLauth Management UI [in /home/nils/python/ldap/app/__init__.py:48]
2021-03-27 13:23:58,900 INFO: GLauth Management UI [in /home/nils/python/ldap/app/__init__.py:48]
2021-03-27 13:24:32,287 INFO: GLauth Management UI [in /home/nils/python/ldap/app/__init__.py:48]
2021-03-27 13:24:41,105 ERROR: Exception on /admin/user/edit/ [GET] [in /home/nils/python/ldap/venv/lib/python3.8/site-packages/flask/app.py:1891]
Traceback (most recent call last):
  File "/home/nils/python/ldap/venv/lib/python3.8/site-packages/flask/app.py", line 2447, in wsgi_app
    response = self.full_dispatch_request()
  File "/home/nils/python/ldap/venv/lib/python3.8/site-packages/flask/app.py", line 1952, in full_dispatch_request
    rv = self.handle_user_exception(e)
  File "/home/nils/python/ldap/venv/lib/python3.8/site-packages/flask/app.py", line 1821, in handle_user_exception
    reraise(exc_type, exc_value, tb)
  File "/home/nils/python/ldap/venv/lib/python3.8/site-packages/flask/_compat.py", line 39, in reraise
    raise value
  File "/home/nils/python/ldap/venv/lib/python3.8/site-packages/flask/app.py", line 1950, in full_dispatch_request
    rv = self.dispatch_request()
  File "/home/nils/python/ldap/venv/lib/python3.8/site-packages/flask/app.py", line 1936, in dispatch_request
    return self.view_functions[rule.endpoint](**req.view_args)
  File "/home/nils/python/ldap/venv/lib/python3.8/site-packages/flask_admin/base.py", line 69, in inner
    return self._run_view(f, *args, **kwargs)
  File "/home/nils/python/ldap/venv/lib/python3.8/site-packages/flask_admin/base.py", line 368, in _run_view
    return fn(self, *args, **kwargs)
  File "/home/nils/python/ldap/venv/lib/python3.8/site-packages/flask_admin/model/base.py", line 2138, in edit_view
    form = self.edit_form(obj=model)
  File "/home/nils/python/ldap/app/adminview.py", line 117, in edit_form
    setattr(form, { "TEST": BooleanField('DummyTest') })
TypeError: setattr expected 3 arguments, got 2
2021-03-27 13:26:02,262 INFO: GLauth Management UI [in /home/nils/python/ldap/app/__init__.py:48]
2021-03-27 13:28:56,776 INFO: GLauth Management UI [in /home/nils/python/ldap/app/__init__.py:48]
2021-03-27 13:47:43,823 INFO: GLauth Management UI [in /home/nils/python/ldap/app/__init__.py:48]
2021-03-27 13:48:10,605 INFO: GLauth Management UI [in /home/nils/python/ldap/app/__init__.py:48]
2021-03-27 16:47:51,602 INFO: GLauth Management UI [in /home/nils/python/ldap/app/__init__.py:48]
2021-03-27 16:48:01,719 INFO: GLauth Management UI [in /home/nils/python/ldap/app/__init__.py:48]
2021-03-27 16:48:06,856 INFO: GLauth Management UI [in /home/nils/python/ldap/app/__init__.py:48]
2021-03-27 16:48:09,541 INFO: GLauth Management UI [in /home/nils/python/ldap/app/__init__.py:48]
2021-03-27 16:48:18,131 INFO: GLauth Management UI [in /home/nils/python/ldap/app/__init__.py:48]
2021-03-27 16:48:29,673 INFO: GLauth Management UI [in /home/nils/python/ldap/app/__init__.py:48]
2021-03-27 16:50:37,368 INFO: GLauth Management UI [in /home/nils/python/ldap/app/__init__.py:48]
2021-03-27 17:03:21,438 INFO: GLauth Management UI [in /home/nils/python/ldap/app/__init__.py:48]
2021-03-27 17:06:43,671 INFO: GLauth Management UI [in /home/nils/python/ldap/app/__init__.py:48]
2021-03-27 17:10:13,881 INFO: GLauth Management UI [in /home/nils/python/ldap/app/__init__.py:48]
2021-03-27 17:10:18,010 ERROR: Exception on /admin/glauthconfig/ [POST] [in /home/nils/python/ldap/venv/lib/python3.8/site-packages/flask/app.py:1891]
Traceback (most recent call last):
  File "/home/nils/python/ldap/venv/lib/python3.8/site-packages/flask/app.py", line 2447, in wsgi_app
    response = self.full_dispatch_request()
  File "/home/nils/python/ldap/venv/lib/python3.8/site-packages/flask/app.py", line 1952, in full_dispatch_request
    rv = self.handle_user_exception(e)
  File "/home/nils/python/ldap/venv/lib/python3.8/site-packages/flask/app.py", line 1821, in handle_user_exception
    reraise(exc_type, exc_value, tb)
  File "/home/nils/python/ldap/venv/lib/python3.8/site-packages/flask/_compat.py", line 39, in reraise
    raise value
  File "/home/nils/python/ldap/venv/lib/python3.8/site-packages/flask/app.py", line 1950, in full_dispatch_request
    rv = self.dispatch_request()
  File "/home/nils/python/ldap/venv/lib/python3.8/site-packages/flask/app.py", line 1936, in dispatch_request
    return self.view_functions[rule.endpoint](**req.view_args)
  File "/home/nils/python/ldap/venv/lib/python3.8/site-packages/flask_admin/base.py", line 69, in inner
    return self._run_view(f, *args, **kwargs)
  File "/home/nils/python/ldap/venv/lib/python3.8/site-packages/flask_admin/base.py", line 368, in _run_view
    return fn(self, *args, **kwargs)
  File "/home/nils/python/ldap/app/adminview.py", line 237, in index
    create_glauth_config()
  File "/home/nils/python/ldap/app/glauth.py", line 51, in create_glauth_config
    if len(group.included_in) > 0:
TypeError: object of type 'AppenderBaseQuery' has no len()
2021-03-27 17:13:11,256 INFO: GLauth Management UI [in /home/nils/python/ldap/app/__init__.py:48]
2021-03-27 17:15:12,828 INFO: GLauth Management UI [in /home/nils/python/ldap/app/__init__.py:48]
2021-03-27 17:16:23,392 INFO: GLauth Management UI [in /home/nils/python/ldap/app/__init__.py:48]
2021-03-28 13:34:04,678 INFO: GLauth Management UI [in /home/nils/python/ldap/app/__init__.py:48]
2021-03-28 13:34:58,314 INFO: GLauth Management UI [in /home/nils/python/ldap/app/__init__.py:48]
2021-03-28 13:35:53,638 INFO: GLauth Management UI [in /home/nils/python/ldap/app/__init__.py:48]
2021-03-28 13:36:14,570 INFO: GLauth Management UI [in /home/nils/python/ldap/app/__init__.py:48]
